<?xml version="1.0"?>
<robot xmlns:xacro="http://www.ros.org/wiki/xacro" name="grasslammer_wheel">


    <xacro:property name="wheel_mass" value="2"/>
    <xacro:property name="wheel_radius" value="0.06985"/>
    <xacro:property name="wheel_length" value="0.06"/>

    
    
    <xacro:macro name="grasslammer_wheel" params="wheel_prefix *origin "> <!--**parent-->
        <link name="${wheel_prefix}_wheel">
            
            <visual>
                <geometry>
                    <mesh filename="file://$(find grasslammer2_description)/meshes/rocker_wheel.stl"/>
                </geometry>
            </visual>
            <collision>
                <geometry>
                    <mesh filename="file://$(find grasslammer2_description)/meshes/rocker_wheel.stl"/>
                </geometry>
            </collision>
            <xacro:inertial_cylinder mass="${wheel_mass}" length="${wheel_length}" radius="${wheel_radius}">
                <origin xyz="0.0 0.01 0.0" rpy="1.57 0 0"/>
            </xacro:inertial_cylinder>
        </link>

        <joint name="${wheel_prefix}_hinge" type="continuous">
            <xacro:if value="${wheel_prefix == 'RF' or wheel_prefix == 'RR'}">
                <parent link="right_bar"/>
                <axis xyz="0 -1 0"/>
            </xacro:if>
            <xacro:if value="${wheel_prefix == 'LF' or wheel_prefix == 'LR'}">
                <parent link="left_bar"/>
                <axis xyz="0 1 0"/>
            </xacro:if> 
            <child link="${wheel_prefix}_wheel"/>
            <xacro:insert_block name="origin"/>
            <limit effort="10000" velocity="1000"/>
        </joint>   
        
        <gazebo reference="${wheel_prefix}_wheel">
            <kp>1e6</kp>
            <kd>1.0</kd>
            <mu1>0.8</mu1>
            <mu2>0.3</mu2>
            <fdir1 value="1 0 0"/>

            <material>Gazebo/Gray</material>
        </gazebo>
        


    </xacro:macro>



    


</robot>
